No sentence-transformers model found with name BAAI/bge-large-en-v1.5. Creating a new one with mean pooling.
Traceback (most recent call last):
  File "<string>", line 1, in <module>
RuntimeError: Dora Runtime raised an error.

Caused by:
   0: main task failed
   1: failed to init an operator
   2: failed to init python operator
   3: Traceback (most recent call last):
        File "<string>", line 1, in <module>
        File "/dora/examples/python-operator-dataflow/sentence_transformers_op.py", line 55, in __init__
          self.model = SentenceTransformer("BAAI/bge-large-en-v1.5")
        File "/dora/examples/python-operator-dataflow/.venv/lib/python3.10/site-packages/sentence_transformers/SentenceTransformer.py", line 339, in __init__
          modules = self._load_auto_model(
        File "/dora/examples/python-operator-dataflow/.venv/lib/python3.10/site-packages/sentence_transformers/SentenceTransformer.py", line 2061, in _load_auto_model
          transformer_model = Transformer(
        File "/dora/examples/python-operator-dataflow/.venv/lib/python3.10/site-packages/sentence_transformers/models/Transformer.py", line 87, in __init__
          config, is_peft_model = self._load_config(model_name_or_path, cache_dir, backend, config_args)
        File "/dora/examples/python-operator-dataflow/.venv/lib/python3.10/site-packages/sentence_transformers/models/Transformer.py", line 128, in _load_config
          find_adapter_config_file(
        File "/dora/examples/python-operator-dataflow/.venv/lib/python3.10/site-packages/transformers/utils/peft_utils.py", line 88, in find_adapter_config_file
          adapter_cached_filename = cached_file(
        File "/dora/examples/python-operator-dataflow/.venv/lib/python3.10/site-packages/transformers/utils/hub.py", line 312, in cached_file
          file = cached_files(path_or_repo_id=path_or_repo_id, filenames=[filename], **kwargs)
        File "/dora/examples/python-operator-dataflow/.venv/lib/python3.10/site-packages/transformers/utils/hub.py", line 557, in cached_files
          raise e
        File "/dora/examples/python-operator-dataflow/.venv/lib/python3.10/site-packages/transformers/utils/hub.py", line 470, in cached_files
          hf_hub_download(
        File "/dora/examples/python-operator-dataflow/.venv/lib/python3.10/site-packages/huggingface_hub/utils/_validators.py", line 114, in _inner_fn
          return fn(*args, **kwargs)
        File "/dora/examples/python-operator-dataflow/.venv/lib/python3.10/site-packages/huggingface_hub/file_download.py", line 1008, in hf_hub_download
          return _hf_hub_download_to_cache_dir(
        File "/dora/examples/python-operator-dataflow/.venv/lib/python3.10/site-packages/huggingface_hub/file_download.py", line 1071, in _hf_hub_download_to_cache_dir
          (url_to_download, etag, commit_hash, expected_size, xet_file_data, head_call_error) = _get_metadata_or_catch_error(
        File "/dora/examples/python-operator-dataflow/.venv/lib/python3.10/site-packages/huggingface_hub/file_download.py", line 1533, in _get_metadata_or_catch_error
          metadata = get_hf_file_metadata(
        File "/dora/examples/python-operator-dataflow/.venv/lib/python3.10/site-packages/huggingface_hub/utils/_validators.py", line 114, in _inner_fn
          return fn(*args, **kwargs)
        File "/dora/examples/python-operator-dataflow/.venv/lib/python3.10/site-packages/huggingface_hub/file_download.py", line 1450, in get_hf_file_metadata
          r = _request_wrapper(
        File "/dora/examples/python-operator-dataflow/.venv/lib/python3.10/site-packages/huggingface_hub/file_download.py", line 286, in _request_wrapper
          response = _request_wrapper(
        File "/dora/examples/python-operator-dataflow/.venv/lib/python3.10/site-packages/huggingface_hub/file_download.py", line 309, in _request_wrapper
          response = http_backoff(method=method, url=url, **params, retry_on_exceptions=(), retry_on_status_codes=(429,))
        File "/dora/examples/python-operator-dataflow/.venv/lib/python3.10/site-packages/huggingface_hub/utils/_http.py", line 310, in http_backoff
          response = session.request(method=method, url=url, **kwargs)
        File "/dora/examples/python-operator-dataflow/.venv/lib/python3.10/site-packages/requests/sessions.py", line 589, in request
          resp = self.send(prep, **send_kwargs)
        File "/dora/examples/python-operator-dataflow/.venv/lib/python3.10/site-packages/requests/sessions.py", line 703, in send
          r = adapter.send(request, **kwargs)
        File "/dora/examples/python-operator-dataflow/.venv/lib/python3.10/site-packages/huggingface_hub/utils/_http.py", line 96, in send
          return super().send(request, *args, **kwargs)
        File "/dora/examples/python-operator-dataflow/.venv/lib/python3.10/site-packages/requests/adapters.py", line 698, in send
          raise SSLError(e, request=request)

      SSLError: (MaxRetryError("HTTPSConnectionPool(host='huggingface.co', port=443): Max retries exceeded with url: /BAAI/bge-large-en-v1.5/resolve/main/adapter_config.json (Caused by SSLError(SSLEOFError(8, '[SSL: UNEXPECTED_EOF_WHILE_READING] EOF occurred in violation of protocol (_ssl.c:1017)')))"), '(Request ID: 09100503-be5b-4e3e-b9bc-a256898b0461)')

Location:
    binaries/runtime/src/operator/python.rs:29:9
